#VRML_SIM R2021a utf8
WorldInfo {
  basicTimeStep 16
  coordinateSystem "NUE"
}
Viewpoint {
  orientation 1 0 0 4.71238898038469
  position 0.17934584635660358 2.670737090849305 0.0517723117328315
}
TexturedBackground {
}
TexturedBackgroundLight {
}
RectangleArena {
  floorSize 3 3
}
WoodenBox {
  translation 0.51472 0.15 0.288634
  rotation 0 1 0 0.785398
  size 0.3 0.3 0.3
}
WoodenBox {
  translation -0.422468 0.15 0.113786
  rotation 0 1 0 0.261799
  name "wooden box(1)"
  size 0.3 0.3 0.3
}
WoodenBox {
  translation 0.445491 0.15 -0.201572
  rotation 0 1 0 0.261799
  name "wooden box(2)"
  size 0.3 0.3 0.3
}
WoodenBox {
  translation -0.128256 0.15 0.514311
  rotation 0 1 0 0.785398
  name "wooden box(3)"
  size 0.3 0.3 0.3
}
Robot {
  translation 0 0.1 0
  rotation 0 1 0 1.0472
  children [
    DEF BODY Shape {
      appearance PBRAppearance {
        baseColor 1 0 0
        metalness 0
      }
      geometry Box {
        size 0.1 0.04 0.2
      }
    }
    HingeJoint {
      jointParameters HingeJointParameters {
        anchor 0.06 0 0.05
      }
      device [
        RotationalMotor {
          name "Motor1"
        }
      ]
      endPoint DEF WHEEL1 Solid {
        translation 0.06 0 0.05
        rotation 0 0 1 1.5708
        children [
          DEF WHEEL Shape {
            appearance PBRAppearance {
              baseColor 0 0.666667 0
              metalness 0
            }
            geometry Cylinder {
              height 0.02
              radius 0.04
              subdivision 64
            }
          }
        ]
        name "wheel1"
        boundingObject USE WHEEL
        physics DEF WHEEL_PH Physics {
        }
      }
    }
    HingeJoint {
      jointParameters HingeJointParameters {
        anchor -0.06 0 0.05
      }
      device [
        RotationalMotor {
          name "Motor2"
        }
      ]
      endPoint Solid {
        translation -0.06 0 0.05
        rotation 0 0 1 1.5708
        children [
          USE WHEEL
        ]
        name "wheel2"
        boundingObject USE WHEEL
        physics Physics {
        }
      }
    }
    HingeJoint {
      jointParameters HingeJointParameters {
        anchor 0.06 0 -0.05
      }
      device [
        RotationalMotor {
          name "Motor3"
        }
      ]
      endPoint Solid {
        translation 0.06 0 -0.05
        rotation 0 0 1 1.5708
        children [
          USE WHEEL
        ]
        name "wheel3"
        boundingObject USE WHEEL
        physics Physics {
        }
      }
    }
    HingeJoint {
      jointParameters HingeJointParameters {
        anchor -0.06 0 -0.05
      }
      device [
        RotationalMotor {
          name "Motor4"
        }
      ]
      endPoint Solid {
        translation -0.06 0 -0.05
        rotation 0 0 1 1.5708
        children [
          USE WHEEL
        ]
        name "wheel4"
        boundingObject USE WHEEL
        physics Physics {
        }
      }
    }
    DistanceSensor {
      translation 0.03 0 0.1
      rotation 0 1 0 -1.3089996938995747
      children [
        Shape {
          appearance PBRAppearance {
            baseColor 1 0.666667 0
            metalness 0
          }
          geometry Box {
            size 0.01 0.01 0.01
          }
        }
      ]
      name "left distance sensor"
    }
    DistanceSensor {
      translation -0.03 0 0.1
      rotation 0 1 0 -1.8326003061004252
      children [
        Shape {
          appearance PBRAppearance {
            baseColor 1 0.666667 0
            metalness 0
          }
          geometry Box {
            size 0.01 0.01 0.01
          }
        }
      ]
      name "right distance sensor"
    }
  ]
  boundingObject USE BODY
  physics Physics {
  }
  controller "WheelRobot"
}
